Traceback (most recent call last):
  File "/home/dataengineer/.pyenv/versions/3.9.21/bin/airflow", line 8, in <module>
    sys.exit(main())
  File "/home/dataengineer/.pyenv/versions/3.9.21/lib/python3.9/site-packages/airflow/__main__.py", line 62, in main
    args.func(args)
  File "/home/dataengineer/.pyenv/versions/3.9.21/lib/python3.9/site-packages/airflow/cli/cli_config.py", line 49, in command
    return func(*args, **kwargs)
  File "/home/dataengineer/.pyenv/versions/3.9.21/lib/python3.9/site-packages/airflow/utils/cli.py", line 116, in wrapper
    return f(*args, **kwargs)
  File "/home/dataengineer/.pyenv/versions/3.9.21/lib/python3.9/site-packages/airflow/utils/providers_configuration_loader.py", line 55, in wrapped_function
    return func(*args, **kwargs)
  File "/home/dataengineer/.pyenv/versions/3.9.21/lib/python3.9/site-packages/airflow/cli/commands/webserver_command.py", line 485, in webserver
    run_command_with_daemon_option(
  File "/home/dataengineer/.pyenv/versions/3.9.21/lib/python3.9/site-packages/airflow/cli/commands/daemon_utils.py", line 81, in run_command_with_daemon_option
    callback()
  File "/home/dataengineer/.pyenv/versions/3.9.21/lib/python3.9/site-packages/airflow/cli/commands/webserver_command.py", line 488, in <lambda>
    callback=lambda: start_and_monitor_gunicorn(args),
  File "/home/dataengineer/.pyenv/versions/3.9.21/lib/python3.9/site-packages/airflow/cli/commands/webserver_command.py", line 471, in start_and_monitor_gunicorn
    gunicorn_master_proc = psutil.Process(gunicorn_master_proc_pid)
  File "/home/dataengineer/.pyenv/versions/3.9.21/lib/python3.9/site-packages/psutil/__init__.py", line 317, in __init__
    self._init(pid)
  File "/home/dataengineer/.pyenv/versions/3.9.21/lib/python3.9/site-packages/psutil/__init__.py", line 363, in _init
    raise NoSuchProcess(pid, msg=msg) from None
psutil.NoSuchProcess: process PID not found (pid=10595)
